[2021-08-14 21:04:49,512] {taskinstance.py:896} INFO - Dependencies all met for <TaskInstance: dag_pag_B.load_data 2021-08-14T21:03:53.746775+00:00 [queued]>
[2021-08-14 21:04:49,525] {taskinstance.py:896} INFO - Dependencies all met for <TaskInstance: dag_pag_B.load_data 2021-08-14T21:03:53.746775+00:00 [queued]>
[2021-08-14 21:04:49,526] {taskinstance.py:1087} INFO - 
--------------------------------------------------------------------------------
[2021-08-14 21:04:49,526] {taskinstance.py:1088} INFO - Starting attempt 1 of 1
[2021-08-14 21:04:49,527] {taskinstance.py:1089} INFO - 
--------------------------------------------------------------------------------
[2021-08-14 21:04:49,541] {taskinstance.py:1107} INFO - Executing <Task(PythonOperator): load_data> on 2021-08-14T21:03:53.746775+00:00
[2021-08-14 21:04:49,545] {standard_task_runner.py:52} INFO - Started process 174 to run task
[2021-08-14 21:04:49,549] {standard_task_runner.py:76} INFO - Running: ['***', 'tasks', 'run', 'dag_pag_B', 'load_data', '2021-08-14T21:03:53.746775+00:00', '--job-id', '51', '--pool', 'default_pool', '--raw', '--subdir', 'DAGS_FOLDER/pag1.py', '--cfg-path', '/tmp/tmp_k4ex8zq', '--error-file', '/tmp/tmpmo5v2l4o']
[2021-08-14 21:04:49,550] {standard_task_runner.py:77} INFO - Job 51: Subtask load_data
[2021-08-14 21:04:49,593] {logging_mixin.py:104} INFO - Running <TaskInstance: dag_pag_B.load_data 2021-08-14T21:03:53.746775+00:00 [running]> on host aa5fbd5b1745
[2021-08-14 21:04:49,640] {taskinstance.py:1302} INFO - Exporting the following env vars:
AIRFLOW_CTX_DAG_OWNER=***
AIRFLOW_CTX_DAG_ID=dag_pag_B
AIRFLOW_CTX_TASK_ID=load_data
AIRFLOW_CTX_EXECUTION_DATE=2021-08-14T21:03:53.746775+00:00
AIRFLOW_CTX_DAG_RUN_ID=manual__2021-08-14T21:03:53.746775+00:00
[2021-08-14 21:04:49,641] {pag1.py:108} INFO - LOAD-DATA STARTED
[2021-08-14 21:04:49,694] {pag1.py:113} INFO - LOAD-DATA Getting formatted data from queue
[2021-08-14 21:04:55,075] {pag1.py:116} INFO - LOAD-DATA Transforming formatted data to dataframe
[2021-08-14 21:04:59,581] {pag1.py:120} INFO - LOAD-DATA Saving formatted data to MySQL database
[2021-08-14 21:05:00,113] {taskinstance.py:1501} ERROR - Task failed with exception
Traceback (most recent call last):
  File "/home/airflow/.local/lib/python3.6/site-packages/sqlalchemy/engine/base.py", line 2336, in _wrap_pool_connect
    return fn()
  File "/home/airflow/.local/lib/python3.6/site-packages/sqlalchemy/pool/base.py", line 364, in connect
    return _ConnectionFairy._checkout(self)
  File "/home/airflow/.local/lib/python3.6/site-packages/sqlalchemy/pool/base.py", line 778, in _checkout
    fairy = _ConnectionRecord.checkout(pool)
  File "/home/airflow/.local/lib/python3.6/site-packages/sqlalchemy/pool/base.py", line 495, in checkout
    rec = pool._do_get()
  File "/home/airflow/.local/lib/python3.6/site-packages/sqlalchemy/pool/impl.py", line 140, in _do_get
    self._dec_overflow()
  File "/home/airflow/.local/lib/python3.6/site-packages/sqlalchemy/util/langhelpers.py", line 70, in __exit__
    with_traceback=exc_tb,
  File "/home/airflow/.local/lib/python3.6/site-packages/sqlalchemy/util/compat.py", line 182, in raise_
    raise exception
  File "/home/airflow/.local/lib/python3.6/site-packages/sqlalchemy/pool/impl.py", line 137, in _do_get
    return self._create_connection()
  File "/home/airflow/.local/lib/python3.6/site-packages/sqlalchemy/pool/base.py", line 309, in _create_connection
    return _ConnectionRecord(self)
  File "/home/airflow/.local/lib/python3.6/site-packages/sqlalchemy/pool/base.py", line 440, in __init__
    self.__connect(first_connect_check=True)
  File "/home/airflow/.local/lib/python3.6/site-packages/sqlalchemy/pool/base.py", line 661, in __connect
    pool.logger.debug("Error on connect(): %s", e)
  File "/home/airflow/.local/lib/python3.6/site-packages/sqlalchemy/util/langhelpers.py", line 70, in __exit__
    with_traceback=exc_tb,
  File "/home/airflow/.local/lib/python3.6/site-packages/sqlalchemy/util/compat.py", line 182, in raise_
    raise exception
  File "/home/airflow/.local/lib/python3.6/site-packages/sqlalchemy/pool/base.py", line 656, in __connect
    connection = pool._invoke_creator(self)
  File "/home/airflow/.local/lib/python3.6/site-packages/sqlalchemy/engine/strategies.py", line 114, in connect
    return dialect.connect(*cargs, **cparams)
  File "/home/airflow/.local/lib/python3.6/site-packages/sqlalchemy/engine/default.py", line 508, in connect
    return self.dbapi.connect(*cargs, **cparams)
  File "/home/airflow/.local/lib/python3.6/site-packages/MySQLdb/__init__.py", line 130, in Connect
    return Connection(*args, **kwargs)
  File "/home/airflow/.local/lib/python3.6/site-packages/MySQLdb/connections.py", line 185, in __init__
    super().__init__(*args, **kwargs2)
MySQLdb._exceptions.OperationalError: (1049, "Unknown database 'db'")

The above exception was the direct cause of the following exception:

Traceback (most recent call last):
  File "/home/airflow/.local/lib/python3.6/site-packages/airflow/models/taskinstance.py", line 1157, in _run_raw_task
    self._prepare_and_execute_task_with_callbacks(context, task)
  File "/home/airflow/.local/lib/python3.6/site-packages/airflow/models/taskinstance.py", line 1331, in _prepare_and_execute_task_with_callbacks
    result = self._execute_task(context, task_copy)
  File "/home/airflow/.local/lib/python3.6/site-packages/airflow/models/taskinstance.py", line 1356, in _execute_task
    result = task_copy.execute(context=context)
  File "/home/airflow/.local/lib/python3.6/site-packages/airflow/operators/python.py", line 150, in execute
    return_value = self.execute_callable()
  File "/home/airflow/.local/lib/python3.6/site-packages/airflow/operators/python.py", line 161, in execute_callable
    return self.python_callable(*self.op_args, **self.op_kwargs)
  File "/opt/airflow/dags/pag1.py", line 122, in _load_data
    df.to_sql('transactions', engine, if_exists='append', index=False)
  File "/home/airflow/.local/lib/python3.6/site-packages/pandas/core/generic.py", line 2615, in to_sql
    method=method,
  File "/home/airflow/.local/lib/python3.6/site-packages/pandas/io/sql.py", line 598, in to_sql
    method=method,
  File "/home/airflow/.local/lib/python3.6/site-packages/pandas/io/sql.py", line 1393, in to_sql
    table.create()
  File "/home/airflow/.local/lib/python3.6/site-packages/pandas/io/sql.py", line 721, in create
    if self.exists():
  File "/home/airflow/.local/lib/python3.6/site-packages/pandas/io/sql.py", line 708, in exists
    return self.pd_sql.has_table(self.name, self.schema)
  File "/home/airflow/.local/lib/python3.6/site-packages/pandas/io/sql.py", line 1431, in has_table
    self.connectable.dialect.has_table, name, schema or self.meta.schema
  File "/home/airflow/.local/lib/python3.6/site-packages/sqlalchemy/engine/base.py", line 2211, in run_callable
    with self._contextual_connect() as conn:
  File "/home/airflow/.local/lib/python3.6/site-packages/sqlalchemy/engine/base.py", line 2302, in _contextual_connect
    self._wrap_pool_connect(self.pool.connect, None),
  File "/home/airflow/.local/lib/python3.6/site-packages/sqlalchemy/engine/base.py", line 2340, in _wrap_pool_connect
    e, dialect, self
  File "/home/airflow/.local/lib/python3.6/site-packages/sqlalchemy/engine/base.py", line 1584, in _handle_dbapi_exception_noconnection
    sqlalchemy_exception, with_traceback=exc_info[2], from_=e
  File "/home/airflow/.local/lib/python3.6/site-packages/sqlalchemy/util/compat.py", line 182, in raise_
    raise exception
  File "/home/airflow/.local/lib/python3.6/site-packages/sqlalchemy/engine/base.py", line 2336, in _wrap_pool_connect
    return fn()
  File "/home/airflow/.local/lib/python3.6/site-packages/sqlalchemy/pool/base.py", line 364, in connect
    return _ConnectionFairy._checkout(self)
  File "/home/airflow/.local/lib/python3.6/site-packages/sqlalchemy/pool/base.py", line 778, in _checkout
    fairy = _ConnectionRecord.checkout(pool)
  File "/home/airflow/.local/lib/python3.6/site-packages/sqlalchemy/pool/base.py", line 495, in checkout
    rec = pool._do_get()
  File "/home/airflow/.local/lib/python3.6/site-packages/sqlalchemy/pool/impl.py", line 140, in _do_get
    self._dec_overflow()
  File "/home/airflow/.local/lib/python3.6/site-packages/sqlalchemy/util/langhelpers.py", line 70, in __exit__
    with_traceback=exc_tb,
  File "/home/airflow/.local/lib/python3.6/site-packages/sqlalchemy/util/compat.py", line 182, in raise_
    raise exception
  File "/home/airflow/.local/lib/python3.6/site-packages/sqlalchemy/pool/impl.py", line 137, in _do_get
    return self._create_connection()
  File "/home/airflow/.local/lib/python3.6/site-packages/sqlalchemy/pool/base.py", line 309, in _create_connection
    return _ConnectionRecord(self)
  File "/home/airflow/.local/lib/python3.6/site-packages/sqlalchemy/pool/base.py", line 440, in __init__
    self.__connect(first_connect_check=True)
  File "/home/airflow/.local/lib/python3.6/site-packages/sqlalchemy/pool/base.py", line 661, in __connect
    pool.logger.debug("Error on connect(): %s", e)
  File "/home/airflow/.local/lib/python3.6/site-packages/sqlalchemy/util/langhelpers.py", line 70, in __exit__
    with_traceback=exc_tb,
  File "/home/airflow/.local/lib/python3.6/site-packages/sqlalchemy/util/compat.py", line 182, in raise_
    raise exception
  File "/home/airflow/.local/lib/python3.6/site-packages/sqlalchemy/pool/base.py", line 656, in __connect
    connection = pool._invoke_creator(self)
  File "/home/airflow/.local/lib/python3.6/site-packages/sqlalchemy/engine/strategies.py", line 114, in connect
    return dialect.connect(*cargs, **cparams)
  File "/home/airflow/.local/lib/python3.6/site-packages/sqlalchemy/engine/default.py", line 508, in connect
    return self.dbapi.connect(*cargs, **cparams)
  File "/home/airflow/.local/lib/python3.6/site-packages/MySQLdb/__init__.py", line 130, in Connect
    return Connection(*args, **kwargs)
  File "/home/airflow/.local/lib/python3.6/site-packages/MySQLdb/connections.py", line 185, in __init__
    super().__init__(*args, **kwargs2)
sqlalchemy.exc.OperationalError: (MySQLdb._exceptions.OperationalError) (1049, "Unknown database 'db'")
(Background on this error at: http://sqlalche.me/e/13/e3q8)
[2021-08-14 21:05:00,143] {taskinstance.py:1551} INFO - Marking task as FAILED. dag_id=dag_pag_B, task_id=load_data, execution_date=20210814T210353, start_date=20210814T210449, end_date=20210814T210500
[2021-08-14 21:05:00,235] {local_task_job.py:149} INFO - Task exited with return code 1
